Traceback (most recent call last):
  File "/home/jose/.local/lib/python3.12/site-packages/jupyter_cache/executors/utils.py", line 58, in single_nb_execution
    executenb(
  File "/usr/lib/python3/dist-packages/nbclient/client.py", line 1305, in execute
    return NotebookClient(nb=nb, resources=resources, km=km, **kwargs).execute()
           ^^^^^^^^^^^^^^^^^^^^^^^^^^^^^^^^^^^^^^^^^^^^^^^^^^^^^^^^^^^^^^^^^^^^^
  File "/usr/lib/python3/dist-packages/jupyter_core/utils/__init__.py", line 168, in wrapped
    return loop.run_until_complete(inner)
           ^^^^^^^^^^^^^^^^^^^^^^^^^^^^^^
  File "/usr/lib/python3.12/asyncio/base_events.py", line 687, in run_until_complete
    return future.result()
           ^^^^^^^^^^^^^^^
  File "/usr/lib/python3/dist-packages/nbclient/client.py", line 705, in async_execute
    await self.async_execute_cell(
  File "/usr/lib/python3/dist-packages/nbclient/client.py", line 1058, in async_execute_cell
    await self._check_raise_for_error(cell, cell_index, exec_reply)
  File "/usr/lib/python3/dist-packages/nbclient/client.py", line 914, in _check_raise_for_error
    raise CellExecutionError.from_cell_and_msg(cell, exec_reply_content)
nbclient.exceptions.CellExecutionError: An error occurred while executing the following cell:
------------------
for (let i = 0; i < 10; i++) {
  console.log(i); // Imprime nÃºmeros del 0 al 9
}

console.log(i); // Error: i is not defined
------------------

----- stdout -----
[33m0[39m
----- stdout -----
[33m1[39m
----- stdout -----
[33m2[39m
----- stdout -----
[33m3[39m
----- stdout -----
[33m4[39m
----- stdout -----
[33m5[39m
----- stdout -----
[33m6[39m
----- stdout -----
[33m7[39m
----- stdout -----
[33m8[39m
----- stdout -----
[33m9[39m
------------------

Stack trace:
ReferenceError: i is not defined
    at <anonymous>:4:13

